Workbook

Sheet Calidades_Proveedores
B2: Fecha | C2: Proveedor | D2: FUENTE | E2: TONC | F2: %SiO2 | G2: %CaO2
B3: 44805 | C3: Carbopar | D3: =IF(ISNUMBER(MATCH(ING_PRV[[#This Row],[Proveedor]],PARAMETROS!$A$2:$A$8,0)),"COMPRADA", IF(ISNUMBER(MATCH(ING_PRV[[#This Row],[Proveedor]],PARAMETROS!$B$2:$B$8,0)),"PROPIA","NA") ) -> COMPRADA | E3: 64.53 | F3: 1.6692 | G3: 52.671786
B4: 44806 | C4: Carbopar | D4: =IF(ISNUMBER(MATCH(ING_PRV[[#This Row],[Proveedor]],PARAMETROS!$A$2:$A$8,0)),"COMPRADA", IF(ISNUMBER(MATCH(ING_PRV[[#This Row],[Proveedor]],PARAMETROS!$B$2:$B$8,0)),"PROPIA","NA") ) -> COMPRADA | E4: 166.15 | F4: 2.854225 | G4: 51.947974
B5: 44809 | C5: Carbopar | D5: =IF(ISNUMBER(MATCH(ING_PRV[[#This Row],[Proveedor]],PARAMETROS!$A$2:$A$8,0)),"COMPRADA", IF(ISNUMBER(MATCH(ING_PRV[[#This Row],[Proveedor]],PARAMETROS!$B$2:$B$8,0)),"PROPIA","NA") ) -> COMPRADA | E5: 173.9 | F5: 6.099 | G5: 48.496958
B6: 44810 | C6: Carbopar | D6: =IF(ISNUMBER(MATCH(ING_PRV[[#This Row],[Proveedor]],PARAMETROS!$A$2:$A$8,0)),"COMPRADA", IF(ISNUMBER(MATCH(ING_PRV[[#This Row],[Proveedor]],PARAMETROS!$B$2:$B$8,0)),"PROPIA","NA") ) -> COMPRADA | E6: 198.47 | F6: 1.613025 | G6: 52.499807
B7: 44811 | C7: Carbopar | D7: =IF(ISNUMBER(MATCH(ING_PRV[[#This Row],[Proveedor]],PARAMETROS!$A$2:$A$8,0)),"COMPRADA", IF(ISNUMBER(MATCH(ING_PRV[[#This Row],[Proveedor]],PARAMETROS!$B$2:$B$8,0)),"PROPIA","NA") ) -> COMPRADA | E7: 259.96 | F7: 4.62775 | G7: 50.195522
B8: 44812 | C8: Carbopar | D8: =IF(ISNUMBER(MATCH(ING_PRV[[#This Row],[Proveedor]],PARAMETROS!$A$2:$A$8,0)),"COMPRADA", IF(ISNUMBER(MATCH(ING_PRV[[#This Row],[Proveedor]],PARAMETROS!$B$2:$B$8,0)),"PROPIA","NA") ) -> COMPRADA | E8: 161.07 | F8: 3.646025 | G8: 50.956348
B9: 44813 | C9: Carbopar | D9: =IF(ISNUMBER(MATCH(ING_PRV[[#This Row],[Proveedor]],PARAMETROS!$A$2:$A$8,0)),"COMPRADA", IF(ISNUMBER(MATCH(ING_PRV[[#This Row],[Proveedor]],PARAMETROS!$B$2:$B$8,0)),"PROPIA","NA") ) -> COMPRADA | E9: 292.94 | F9: 5.2858 | G9: 50.655298
B10: 44814 | C10: Carbopar | D10: =IF(ISNUMBER(MATCH(ING_PRV[[#This Row],[Proveedor]],PARAMETROS!$A$2:$A$8,0)),"COMPRADA", IF(ISNUMBER(MATCH(ING_PRV[[#This Row],[Proveedor]],PARAMETROS!$B$2:$B$8,0)),"PROPIA","NA") ) -> COMPRADA | E10: 133.81 | F10: 2.0758 | G10: 49.703922
B11: 44816 | C11: Carbopar | D11: =IF(ISNUMBER(MATCH(ING_PRV[[#This Row],[Proveedor]],PARAMETROS!$A$2:$A$8,0)),"COMPRADA", IF(ISNUMBER(MATCH(ING_PRV[[#This Row],[Proveedor]],PARAMETROS!$B$2:$B$8,0)),"PROPIA","NA") ) -> COMPRADA | E11: 137.22 | F11: 2.083825 | G11: 52.525885
B12: 44817 | C12: Carbopar | D12: =IF(ISNUMBER(MATCH(ING_PRV[[#This Row],[Proveedor]],PARAMETROS!$A$2:$A$8,0)),"COMPRADA", IF(ISNUMBER(MATCH(ING_PRV[[#This Row],[Proveedor]],PARAMETROS!$B$2:$B$8,0)),"PROPIA","NA") ) -> COMPRADA | E12: 170.4 | F12: 2.1 | G12: 51.7
B13: 44818 | C13: Carbopar | D13: =IF(ISNUMBER(MATCH(ING_PRV[[#This Row],[Proveedor]],PARAMETROS!$A$2:$A$8,0)),"COMPRADA", IF(ISNUMBER(MATCH(ING_PRV[[#This Row],[Proveedor]],PARAMETROS!$B$2:$B$8,0)),"PROPIA","NA") ) -> COMPRADA | E13: 234.24 | F13: 4.84 | G13: 51
B14: 44819 | C14: Carbopar | D14: =IF(ISNUMBER(MATCH(ING_PRV[[#This Row],[Proveedor]],PARAMETROS!$A$2:$A$8,0)),"COMPRADA", IF(ISNUMBER(MATCH(ING_PRV[[#This Row],[Proveedor]],PARAMETROS!$B$2:$B$8,0)),"PROPIA","NA") ) -> COMPRADA | E14: 231.94 | F14: 0.61 | G14: 52.8
... B3135: 45923 | C3135: Carbopar | D3135: =IF(ISNUMBER(MATCH(ING_PRV[[#This Row],[Proveedor]],PARAMETROS!$A$2:$A$8,0)),"COMPRADA", IF(ISNUMBER(MATCH(ING_PRV[[#This Row],[Proveedor]],PARAMETROS!$B$2:$B$8,0)),"PROPIA","NA") ) -> COMPRADA | E3135: 162.52 | F3135: 1.2 | G3135: 51.839672
B3136: 45901 | C3136: Caliza Propia | D3136: =IF(ISNUMBER(MATCH(ING_PRV[[#This Row],[Proveedor]],PARAMETROS!$A$2:$A$8,0)),"COMPRADA", IF(ISNUMBER(MATCH(ING_PRV[[#This Row],[Proveedor]],PARAMETROS!$B$2:$B$8,0)),"PROPIA","NA") ) -> PROPIA | E3136: 0
B3137: 45905 | C3137: Caliza Propia | D3137: =IF(ISNUMBER(MATCH(ING_PRV[[#This Row],[Proveedor]],PARAMETROS!$A$2:$A$8,0)),"COMPRADA", IF(ISNUMBER(MATCH(ING_PRV[[#This Row],[Proveedor]],PARAMETROS!$B$2:$B$8,0)),"PROPIA","NA") ) -> PROPIA | E3137: 587.788 | F3137: 16.76 | G3137: 43.4
B3138: 45906 | C3138: Caliza Propia | D3138: =IF(ISNUMBER(MATCH(ING_PRV[[#This Row],[Proveedor]],PARAMETROS!$A$2:$A$8,0)),"COMPRADA", IF(ISNUMBER(MATCH(ING_PRV[[#This Row],[Proveedor]],PARAMETROS!$B$2:$B$8,0)),"PROPIA","NA") ) -> PROPIA | E3138: 145.51 | F3138: 16.76 | G3138: 43.4
B3139: 45908 | C3139: Caliza Propia | D3139: =IF(ISNUMBER(MATCH(ING_PRV[[#This Row],[Proveedor]],PARAMETROS!$A$2:$A$8,0)),"COMPRADA", IF(ISNUMBER(MATCH(ING_PRV[[#This Row],[Proveedor]],PARAMETROS!$B$2:$B$8,0)),"PROPIA","NA") ) -> PROPIA | E3139: 231.645 | F3139: 12.59 | G3139: 47.2
B3140: 45917 | C3140: Caliza Propia | D3140: =IF(ISNUMBER(MATCH(ING_PRV[[#This Row],[Proveedor]],PARAMETROS!$A$2:$A$8,0)),"COMPRADA", IF(ISNUMBER(MATCH(ING_PRV[[#This Row],[Proveedor]],PARAMETROS!$B$2:$B$8,0)),"PROPIA","NA") ) -> PROPIA | E3140: 112.452 | F3140: 8.96 | G3140: 48.5
B3141: 45918 | C3141: Caliza Propia | D3141: =IF(ISNUMBER(MATCH(ING_PRV[[#This Row],[Proveedor]],PARAMETROS!$A$2:$A$8,0)),"COMPRADA", IF(ISNUMBER(MATCH(ING_PRV[[#This Row],[Proveedor]],PARAMETROS!$B$2:$B$8,0)),"PROPIA","NA") ) -> PROPIA | E3141: 327.886 | F3141: 1.26 | G3141: 54.2
B3142: 45919 | C3142: Caliza Propia | D3142: =IF(ISNUMBER(MATCH(ING_PRV[[#This Row],[Proveedor]],PARAMETROS!$A$2:$A$8,0)),"COMPRADA", IF(ISNUMBER(MATCH(ING_PRV[[#This Row],[Proveedor]],PARAMETROS!$B$2:$B$8,0)),"PROPIA","NA") ) -> PROPIA | E3142: 175.982 | F3142: 1.26 | G3142: 54.2
B3143: 45920 | C3143: Caliza Propia | D3143: =IF(ISNUMBER(MATCH(ING_PRV[[#This Row],[Proveedor]],PARAMETROS!$A$2:$A$8,0)),"COMPRADA", IF(ISNUMBER(MATCH(ING_PRV[[#This Row],[Proveedor]],PARAMETROS!$B$2:$B$8,0)),"PROPIA","NA") ) -> PROPIA | E3143: 117.621 | F3143: 2.65 | G3143: 53.1
B3144: 45922 | C3144: Caliza Propia | D3144: =IF(ISNUMBER(MATCH(ING_PRV[[#This Row],[Proveedor]],PARAMETROS!$A$2:$A$8,0)),"COMPRADA", IF(ISNUMBER(MATCH(ING_PRV[[#This Row],[Proveedor]],PARAMETROS!$B$2:$B$8,0)),"PROPIA","NA") ) -> PROPIA | E3144: 196.028 | F3144: 2.97 | G3144: 52.6
B3145: 45898 | C3145: Caliza Propia | D3145: =IF(ISNUMBER(MATCH(ING_PRV[[#This Row],[Proveedor]],PARAMETROS!$A$2:$A$8,0)),"COMPRADA", IF(ISNUMBER(MATCH(ING_PRV[[#This Row],[Proveedor]],PARAMETROS!$B$2:$B$8,0)),"PROPIA","NA") ) -> PROPIA | E3145: 28.222 | F3145: 2.77 | G3145: 52.8
B3146: 45850 | C3146: Caliza Propia | D3146: =IF(ISNUMBER(MATCH(ING_PRV[[#This Row],[Proveedor]],PARAMETROS!$A$2:$A$8,0)),"COMPRADA", IF(ISNUMBER(MATCH(ING_PRV[[#This Row],[Proveedor]],PARAMETROS!$B$2:$B$8,0)),"PROPIA","NA") ) -> PROPIA | E3146: 186.835 | F3146: 2.98 | G3146: 52.6
B3147: 45852 | C3147: Caliza Propia | D3147: =IF(ISNUMBER(MATCH(ING_PRV[[#This Row],[Proveedor]],PARAMETROS!$A$2:$A$8,0)),"COMPRADA", IF(ISNUMBER(MATCH(ING_PRV[[#This Row],[Proveedor]],PARAMETROS!$B$2:$B$8,0)),"PROPIA","NA") ) -> PROPIA | E3147: 222.168 | F3147: 3.61 | G3147: 52.493308
B3148: 45853 | C3148: Caliza Propia | D3148: =IF(ISNUMBER(MATCH(ING_PRV[[#This Row],[Proveedor]],PARAMETROS!$A$2:$A$8,0)),"COMPRADA", IF(ISNUMBER(MATCH(ING_PRV[[#This Row],[Proveedor]],PARAMETROS!$B$2:$B$8,0)),"PROPIA","NA") ) -> PROPIA | E3148: 131.338 | F3148: 3.37 | G3148: 49.099694
... B3178: 45790 | C3178: Caliza Propia | D3178: =IF(ISNUMBER(MATCH(ING_PRV[[#This Row],[Proveedor]],PARAMETROS!$A$2:$A$8,0)),"COMPRADA", IF(ISNUMBER(MATCH(ING_PRV[[#This Row],[Proveedor]],PARAMETROS!$B$2:$B$8,0)),"PROPIA","NA") ) -> PROPIA | E3178: 154.041 | F3178: 5.79405 | G3178: 49.106018
B3179: 45791 | C3179: Caliza Propia | D3179: =IF(ISNUMBER(MATCH(ING_PRV[[#This Row],[Proveedor]],PARAMETROS!$A$2:$A$8,0)),"COMPRADA", IF(ISNUMBER(MATCH(ING_PRV[[#This Row],[Proveedor]],PARAMETROS!$B$2:$B$8,0)),"PROPIA","NA") ) -> PROPIA | E3179: 266.13
B3180: 45792 | C3180: Caliza Propia | D3180: =IF(ISNUMBER(MATCH(ING_PRV[[#This Row],[Proveedor]],PARAMETROS!$A$2:$A$8,0)),"COMPRADA", IF(ISNUMBER(MATCH(ING_PRV[[#This Row],[Proveedor]],PARAMETROS!$B$2:$B$8,0)),"PROPIA","NA") ) -> PROPIA | E3180: 212.986 | F3180: 17.4945 | G3180: 42.911462
B3181: 45796 | C3181: Caliza Propia | D3181: =IF(ISNUMBER(MATCH(ING_PRV[[#This Row],[Proveedor]],PARAMETROS!$A$2:$A$8,0)),"COMPRADA", IF(ISNUMBER(MATCH(ING_PRV[[#This Row],[Proveedor]],PARAMETROS!$B$2:$B$8,0)),"PROPIA","NA") ) -> PROPIA | E3181: 155.34 | F3181: 2.463675 | G3181: 53.523928
B3182: 45797 | C3182: Caliza Propia | D3182: =IF(ISNUMBER(MATCH(ING_PRV[[#This Row],[Proveedor]],PARAMETROS!$A$2:$A$8,0)),"COMPRADA", IF(ISNUMBER(MATCH(ING_PRV[[#This Row],[Proveedor]],PARAMETROS!$B$2:$B$8,0)),"PROPIA","NA") ) -> PROPIA | E3182: 199.199 | F3182: 3.27 | G3182: 52.6
B3183: 45798 | C3183: Caliza Propia | D3183: =IF(ISNUMBER(MATCH(ING_PRV[[#This Row],[Proveedor]],PARAMETROS!$A$2:$A$8,0)),"COMPRADA", IF(ISNUMBER(MATCH(ING_PRV[[#This Row],[Proveedor]],PARAMETROS!$B$2:$B$8,0)),"PROPIA","NA") ) -> PROPIA | E3183: 76.904 | F3183: 3.27 | G3183: 52.6
B3184: 45799 | C3184: Caliza Propia | D3184: =IF(ISNUMBER(MATCH(ING_PRV[[#This Row],[Proveedor]],PARAMETROS!$A$2:$A$8,0)),"COMPRADA", IF(ISNUMBER(MATCH(ING_PRV[[#This Row],[Proveedor]],PARAMETROS!$B$2:$B$8,0)),"PROPIA","NA") ) -> PROPIA | E3184: 416.45 | F3184: 3.27 | G3184: 52.6
B3185: 45800 | C3185: Caliza Propia | D3185: =IF(ISNUMBER(MATCH(ING_PRV[[#This Row],[Proveedor]],PARAMETROS!$A$2:$A$8,0)),"COMPRADA", IF(ISNUMBER(MATCH(ING_PRV[[#This Row],[Proveedor]],PARAMETROS!$B$2:$B$8,0)),"PROPIA","NA") ) -> PROPIA | E3185: 314.805 | F3185: 4.07135 | G3185: 51.747938
B3186: 45801 | C3186: Caliza Propia | D3186: =IF(ISNUMBER(MATCH(ING_PRV[[#This Row],[Proveedor]],PARAMETROS!$A$2:$A$8,0)),"COMPRADA", IF(ISNUMBER(MATCH(ING_PRV[[#This Row],[Proveedor]],PARAMETROS!$B$2:$B$8,0)),"PROPIA","NA") ) -> PROPIA | E3186: 271.812 | F3186: 2.971925 | G3186: 52.186491
B3187: 45803 | C3187: Caliza Propia | D3187: =IF(ISNUMBER(MATCH(ING_PRV[[#This Row],[Proveedor]],PARAMETROS!$A$2:$A$8,0)),"COMPRADA", IF(ISNUMBER(MATCH(ING_PRV[[#This Row],[Proveedor]],PARAMETROS!$B$2:$B$8,0)),"PROPIA","NA") ) -> PROPIA | E3187: 318.455 | F3187: 2.62 | G3187: 52.7
B3188: 45804 | C3188: Caliza Propia | D3188: =IF(ISNUMBER(MATCH(ING_PRV[[#This Row],[Proveedor]],PARAMETROS!$A$2:$A$8,0)),"COMPRADA", IF(ISNUMBER(MATCH(ING_PRV[[#This Row],[Proveedor]],PARAMETROS!$B$2:$B$8,0)),"PROPIA","NA") ) -> PROPIA | E3188: 225.329 | F3188: 2.62 | G3188: 52.7
B3189: 45805 | C3189: Caliza Propia | D3189: =IF(ISNUMBER(MATCH(ING_PRV[[#This Row],[Proveedor]],PARAMETROS!$A$2:$A$8,0)),"COMPRADA", IF(ISNUMBER(MATCH(ING_PRV[[#This Row],[Proveedor]],PARAMETROS!$B$2:$B$8,0)),"PROPIA","NA") ) -> PROPIA | E3189: 306.164 | F3189: 2.62 | G3189: 52.7
B3190: 45806 | C3190: Caliza Propia | D3190: =IF(ISNUMBER(MATCH(ING_PRV[[#This Row],[Proveedor]],PARAMETROS!$A$2:$A$8,0)),"COMPRADA", IF(ISNUMBER(MATCH(ING_PRV[[#This Row],[Proveedor]],PARAMETROS!$B$2:$B$8,0)),"PROPIA","NA") ) -> PROPIA | E3190: 408.166 | F3190: 2.62 | G3190: 52.7
...

Sheet Hoja2
A1: Fecha | B1: Proveedor | C1: FUENTE | D1: TONC | E1: %SiO2 | F1: %CaO2 | G1: Tipo | I1: Promedio Ponderado | J1: =SUMPRODUCT(VERIF[TONC],VERIF[%SiO2])/SUM(VERIF[TONC]) -> 2.0681207 | L1: LI | M1: LS | N1: CONCAT | O1: TON | P1: % | Q1: %Acumulado
A2: 45824 | B2: Malaga | C2: COMPRADA | D2: 35.13 | E2: 0 | F2: 54.554254 | G2: =IF(AND(VERIF[[#This Row],[%SiO2]]>=0,VERIF[[#This Row],[%SiO2]]<1.62),"T1", IF( AND(VERIF[[#This Row],[%SiO2]]>=1.62,VERIF[[#This Row],[%SiO2]]<2.43),"T2", IF( AND(VERIF[[#This Row],[%SiO2]]>=2.43,VERIF[[#This Row],[%SiO2]]<=3.24),"T3","T4")) ) -> T1 | I2: Desviacion Ponderada | J2: {=SQRT(SUMPRODUCT(VERIF[TONC],(VERIF[%SiO2]-$J$1)^2)/SUM(VERIF[TONC]))} -> 1.9972473 | L2: 0 | M2: =+L2+$J$4 -> 0.81 | N2: =CONCATENATE(L2,"-",M2) -> 0-0,81 | O2: =SUMIFS(VERIF[TONC],VERIF[%SiO2],">="&L2,VERIF[%SiO2],"<"&M2) -> 64585.701 | P2: =O2/$J$5 -> 0.2495025 | Q2: =P2 -> 0.2495025
A3: 45862 | B3: Carbopar | C3: COMPRADA | D3: 384.35 | E3: 0 | F3: 54.970316 | G3: =IF(AND(VERIF[[#This Row],[%SiO2]]>=0,VERIF[[#This Row],[%SiO2]]<1.62),"T1", IF( AND(VERIF[[#This Row],[%SiO2]]>=1.62,VERIF[[#This Row],[%SiO2]]<2.43),"T2", IF( AND(VERIF[[#This Row],[%SiO2]]>=2.43,VERIF[[#This Row],[%SiO2]]<=3.24),"T3","T4")) ) -> T1 | I3: K | J3: =ROUNDUP(1+LOG(COUNT(VERIF[%SiO2]),2),0) -> 12 | L3: =M2 -> 0.81 | M3: =+L3+$J$4 -> 1.62 | N3: =CONCATENATE(L3,"-",M3) -> 0,81-1,62 | O3: =SUMIFS(VERIF[TONC],VERIF[%SiO2],">="&L3,VERIF[%SiO2],"<"&M3) -> 59560.701 | P3: =O3/$J$5 -> 0.2300903 | Q3: =P3+Q2 -> 0.4795928
A4: 45878 | B4: Malaga | C4: COMPRADA | D4: 34.38 | E4: 0 | F4: 54.816079 | G4: =IF(AND(VERIF[[#This Row],[%SiO2]]>=0,VERIF[[#This Row],[%SiO2]]<1.62),"T1", IF( AND(VERIF[[#This Row],[%SiO2]]>=1.62,VERIF[[#This Row],[%SiO2]]<2.43),"T2", IF( AND(VERIF[[#This Row],[%SiO2]]>=2.43,VERIF[[#This Row],[%SiO2]]<=3.24),"T3","T4")) ) -> T1 | I4: h | J4: =ROUND((_xlfn.MAXIFS(VERIF[%SiO2],VERIF[%SiO2],"<10")-MIN(VERIF[%SiO2]))/J3,2) -> 0.81 | L4: =M3 -> 1.62 | M4: =+L4+$J$4 -> 2.43 | N4: =CONCATENATE(L4,"-",M4) -> 1,62-2,43 | O4: =SUMIFS(VERIF[TONC],VERIF[%SiO2],">="&L4,VERIF[%SiO2],"<"&M4) -> 59396.086 | P4: =O4/$J$5 -> 0.22945438 | Q4: =P4+Q3 -> 0.70904718
A5: 45884 | B5: Carbopar | C5: COMPRADA | D5: 375.43 | E5: 0.01 | F5: 54.44921 | G5: =IF(AND(VERIF[[#This Row],[%SiO2]]>=0,VERIF[[#This Row],[%SiO2]]<1.62),"T1", IF( AND(VERIF[[#This Row],[%SiO2]]>=1.62,VERIF[[#This Row],[%SiO2]]<2.43),"T2", IF( AND(VERIF[[#This Row],[%SiO2]]>=2.43,VERIF[[#This Row],[%SiO2]]<=3.24),"T3","T4")) ) -> T1 | I5: TON totales | J5: =SUM(VERIF[TONC]) -> 258857.94 | L5: =M4 -> 2.43 | M5: =+L5+$J$4 -> 3.24 | N5: =CONCATENATE(L5,"-",M5) -> 2,43-3,24 | O5: =SUMIFS(VERIF[TONC],VERIF[%SiO2],">="&L5,VERIF[%SiO2],"<"&M5) -> 32800.031 | P5: =O5/$J$5 -> 0.12671055 | Q5: =P5+Q4 -> 0.83575772
A6: 45930 | B6: Carbopar | C6: COMPRADA | D6: 397.1 | E6: 0.01 | F6: 54.1 | G6: =IF(AND(VERIF[[#This Row],[%SiO2]]>=0,VERIF[[#This Row],[%SiO2]]<1.62),"T1", IF( AND(VERIF[[#This Row],[%SiO2]]>=1.62,VERIF[[#This Row],[%SiO2]]<2.43),"T2", IF( AND(VERIF[[#This Row],[%SiO2]]>=2.43,VERIF[[#This Row],[%SiO2]]<=3.24),"T3","T4")) ) -> T1 | L6: =M5 -> 3.24 | M6: =+L6+$J$4 -> 4.05 | N6: =CONCATENATE(L6,"-",M6) -> 3,24-4,05 | O6: =SUMIFS(VERIF[TONC],VERIF[%SiO2],">="&L6,VERIF[%SiO2],"<"&M6) -> 19502.747 | P6: =O6/$J$5 -> 0.075341507 | Q6: =P6+Q5 -> 0.91109923
A7: 45941 | B7: Malaga | C7: COMPRADA | D7: 33.13 | E7: 0.01 | F7: 55.142963 | G7: =IF(AND(VERIF[[#This Row],[%SiO2]]>=0,VERIF[[#This Row],[%SiO2]]<1.62),"T1", IF( AND(VERIF[[#This Row],[%SiO2]]>=1.62,VERIF[[#This Row],[%SiO2]]<2.43),"T2", IF( AND(VERIF[[#This Row],[%SiO2]]>=2.43,VERIF[[#This Row],[%SiO2]]<=3.24),"T3","T4")) ) -> T1 | L7: =M6 -> 4.05 | M7: =+L7+$J$4 -> 4.86 | N7: =CONCATENATE(L7,"-",M7) -> 4,05-4,86 | O7: =SUMIFS(VERIF[TONC],VERIF[%SiO2],">="&L7,VERIF[%SiO2],"<"&M7) -> 9075.33 | P7: =O7/$J$5 -> 0.035059114 | Q7: =P7+Q6 -> 0.94615834
A8: 45944 | B8: Malaga | C8: COMPRADA | D8: 34.15 | E8: 0.01 | F8: 55.142963 | G8: =IF(AND(VERIF[[#This Row],[%SiO2]]>=0,VERIF[[#This Row],[%SiO2]]<1.62),"T1", IF( AND(VERIF[[#This Row],[%SiO2]]>=1.62,VERIF[[#This Row],[%SiO2]]<2.43),"T2", IF( AND(VERIF[[#This Row],[%SiO2]]>=2.43,VERIF[[#This Row],[%SiO2]]<=3.24),"T3","T4")) ) -> T1 | L8: =M7 -> 4.86 | M8: =+L8+$J$4 -> 5.67 | N8: =CONCATENATE(L8,"-",M8) -> 4,86-5,67 | O8: =SUMIFS(VERIF[TONC],VERIF[%SiO2],">="&L8,VERIF[%SiO2],"<"&M8) -> 4218.232 | P8: =O8/$J$5 -> 0.016295548 | Q8: =P8+Q7 -> 0.96245389
A9: 45975 | B9: Carbopar | C9: COMPRADA | D9: 390.41 | E9: 0.03 | F9: 54.090764 | G9: =IF(AND(VERIF[[#This Row],[%SiO2]]>=0,VERIF[[#This Row],[%SiO2]]<1.62),"T1", IF( AND(VERIF[[#This Row],[%SiO2]]>=1.62,VERIF[[#This Row],[%SiO2]]<2.43),"T2", IF( AND(VERIF[[#This Row],[%SiO2]]>=2.43,VERIF[[#This Row],[%SiO2]]<=3.24),"T3","T4")) ) -> T1 | L9: =M8 -> 5.67 | M9: =+L9+$J$4 -> 6.48 | N9: =CONCATENATE(L9,"-",M9) -> 5,67-6,48 | O9: =SUMIFS(VERIF[TONC],VERIF[%SiO2],">="&L9,VERIF[%SiO2],"<"&M9) -> 3148.121 | P9: =O9/$J$5 -> 0.012161578 | Q9: =P9+Q8 -> 0.97461547
A10: 46001 | B10: Carbopar | C10: COMPRADA | D10: 544.54 | E10: 0.03 | F10: 55 | G10: =IF(AND(VERIF[[#This Row],[%SiO2]]>=0,VERIF[[#This Row],[%SiO2]]<1.62),"T1", IF( AND(VERIF[[#This Row],[%SiO2]]>=1.62,VERIF[[#This Row],[%SiO2]]<2.43),"T2", IF( AND(VERIF[[#This Row],[%SiO2]]>=2.43,VERIF[[#This Row],[%SiO2]]<=3.24),"T3","T4")) ) -> T1 | L10: =M9 -> 6.48 | M10: =+L10+$J$4 -> 7.29 | N10: =CONCATENATE(L10,"-",M10) -> 6,48-7,29 | O10: =SUMIFS(VERIF[TONC],VERIF[%SiO2],">="&L10,VERIF[%SiO2],"<"&M10) -> 1287.57 | P10: =O10/$J$5 -> 0.004974041 | Q10: =P10+Q9 -> 0.97958951
A11: 45828 | B11: Carbopar | C11: COMPRADA | D11: 898.45 | E11: 0.04 | F11: 55.201064 | G11: =IF(AND(VERIF[[#This Row],[%SiO2]]>=0,VERIF[[#This Row],[%SiO2]]<1.62),"T1", IF( AND(VERIF[[#This Row],[%SiO2]]>=1.62,VERIF[[#This Row],[%SiO2]]<2.43),"T2", IF( AND(VERIF[[#This Row],[%SiO2]]>=2.43,VERIF[[#This Row],[%SiO2]]<=3.24),"T3","T4")) ) -> T1 | L11: =M10 -> 7.29 | M11: =+L11+$J$4 -> 8.1 | N11: =CONCATENATE(L11,"-",M11) -> 7,29-8,1 | O11: =SUMIFS(VERIF[TONC],VERIF[%SiO2],">="&L11,VERIF[%SiO2],"<"&M11) -> 537.59 | P11: =O11/$J$5 -> 0.0020767762 | Q11: =P11+Q10 -> 0.98166629
A12: 45848 | B12: Carbopar | C12: COMPRADA | D12: 334.71 | E12: 0.04 | F12: 54.726379 | G12: =IF(AND(VERIF[[#This Row],[%SiO2]]>=0,VERIF[[#This Row],[%SiO2]]<1.62),"T1", IF( AND(VERIF[[#This Row],[%SiO2]]>=1.62,VERIF[[#This Row],[%SiO2]]<2.43),"T2", IF( AND(VERIF[[#This Row],[%SiO2]]>=2.43,VERIF[[#This Row],[%SiO2]]<=3.24),"T3","T4")) ) -> T1 | L12: =M11 -> 8.1 | M12: =+L12+$J$4 -> 8.91 | N12: =CONCATENATE(L12,"-",M12) -> 8,1-8,91 | O12: =SUMIFS(VERIF[TONC],VERIF[%SiO2],">="&L12,VERIF[%SiO2],"<"&M12) -> 1391.973 | P12: =O12/$J$5 -> 0.0053773626 | Q12: =P12+Q11 -> 0.98704365
A13: 45966 | B13: Malaga | C13: COMPRADA | D13: 192.46 | E13: 0.04 | F13: 54.878671 | G13: =IF(AND(VERIF[[#This Row],[%SiO2]]>=0,VERIF[[#This Row],[%SiO2]]<1.62),"T1", IF( AND(VERIF[[#This Row],[%SiO2]]>=1.62,VERIF[[#This Row],[%SiO2]]<2.43),"T2", IF( AND(VERIF[[#This Row],[%SiO2]]>=2.43,VERIF[[#This Row],[%SiO2]]<=3.24),"T3","T4")) ) -> T1 | L13: =M12 -> 8.91 | M13: =+L13+$J$4 -> 9.72 | N13: =CONCATENATE(L13,"-",M13) -> 8,91-9,72 | O13: =SUMIFS(VERIF[TONC],VERIF[%SiO2],">="&L13,VERIF[%SiO2],"<"&M13) -> 387.282 | P13: =O13/$J$5 -> 0.0014961179 | Q13: =P13+Q12 -> 0.98853977
A14: 45937 | B14: Malaga | C14: COMPRADA | D14: 175.65 | E14: 0.05 | F14: 54.945697 | G14: =IF(AND(VERIF[[#This Row],[%SiO2]]>=0,VERIF[[#This Row],[%SiO2]]<1.62),"T1", IF( AND(VERIF[[#This Row],[%SiO2]]>=1.62,VERIF[[#This Row],[%SiO2]]<2.43),"T2", IF( AND(VERIF[[#This Row],[%SiO2]]>=2.43,VERIF[[#This Row],[%SiO2]]<=3.24),"T3","T4")) ) -> T1 | L14: =M13 -> 9.72 | M14: =+L14+$J$4 -> 10.53 | N14: =CONCATENATE(L14,"-",M14) -> 9,72-10,53 | O14: =SUMIFS(VERIF[TONC],VERIF[%SiO2],">="&L14,VERIF[%SiO2],"<"&M14) -> 147.92 | P14: =O14/$J$5 -> 0.00057143313 | Q14: =P14+Q13 -> 0.9891112
A15: 45947 | B15: Carbopar | C15: COMPRADA | D15: 428.63 | E15: 0.05 | F15: 54.9 | G15: =IF(AND(VERIF[[#This Row],[%SiO2]]>=0,VERIF[[#This Row],[%SiO2]]<1.62),"T1", IF( AND(VERIF[[#This Row],[%SiO2]]>=1.62,VERIF[[#This Row],[%SiO2]]<2.43),"T2", IF( AND(VERIF[[#This Row],[%SiO2]]>=2.43,VERIF[[#This Row],[%SiO2]]<=3.24),"T3","T4")) ) -> T1 | L15: =M14 -> 10.53 | M15: 100 | N15: =CONCATENATE(L15,"-",M15) -> 10,53-100 | O15: =SUMIFS(VERIF[TONC],VERIF[%SiO2],">="&L15,VERIF[%SiO2],"<"&M15) -> 2818.652 | P15: =O15/$J$5 -> 0.010888799 | Q15: =P15+Q14 -> 1
A16: 46002 | B16: Carbopar | C16: COMPRADA | D16: 439.52 | E16: 0.05 | F16: 55.1 | G16: =IF(AND(VERIF[[#This Row],[%SiO2]]>=0,VERIF[[#This Row],[%SiO2]]<1.62),"T1", IF( AND(VERIF[[#This Row],[%SiO2]]>=1.62,VERIF[[#This Row],[%SiO2]]<2.43),"T2", IF( AND(VERIF[[#This Row],[%SiO2]]>=2.43,VERIF[[#This Row],[%SiO2]]<=3.24),"T3","T4")) ) -> T1
A17: 45853 | B17: Carbopar | C17: COMPRADA | D17: 285.3 | E17: 0.06 | F17: 53.251389 | G17: =IF(AND(VERIF[[#This Row],[%SiO2]]>=0,VERIF[[#This Row],[%SiO2]]<1.62),"T1", IF( AND(VERIF[[#This Row],[%SiO2]]>=1.62,VERIF[[#This Row],[%SiO2]]<2.43),"T2", IF( AND(VERIF[[#This Row],[%SiO2]]>=2.43,VERIF[[#This Row],[%SiO2]]<=3.24),"T3","T4")) ) -> T1
A18: 45821 | B18: Malaga | C18: COMPRADA | D18: 108.51 | E18: 0.07 | F18: 53.952069 | G18: =IF(AND(VERIF[[#This Row],[%SiO2]]>=0,VERIF[[#This Row],[%SiO2]]<1.62),"T1", IF( AND(VERIF[[#This Row],[%SiO2]]>=1.62,VERIF[[#This Row],[%SiO2]]<2.43),"T2", IF( AND(VERIF[[#This Row],[%SiO2]]>=2.43,VERIF[[#This Row],[%SiO2]]<=3.24),"T3","T4")) ) -> T1
A19: 45968 | B19: Carbopar | C19: COMPRADA | D19: 95.19 | E19: 0.07 | F19: 54.8 | G19: =IF(AND(VERIF[[#This Row],[%SiO2]]>=0,VERIF[[#This Row],[%SiO2]]<1.62),"T1", IF( AND(VERIF[[#This Row],[%SiO2]]>=1.62,VERIF[[#This Row],[%SiO2]]<2.43),"T2", IF( AND(VERIF[[#This Row],[%SiO2]]>=2.43,VERIF[[#This Row],[%SiO2]]<=3.24),"T3","T4")) ) -> T1
A20: 45828 | B20: Malaga | C20: COMPRADA | D20: 109.56 | E20: 0.08 | F20: 54.581739 | G20: =IF(AND(VERIF[[#This Row],[%SiO2]]>=0,VERIF[[#This Row],[%SiO2]]<1.62),"T1", IF( AND(VERIF[[#This Row],[%SiO2]]>=1.62,VERIF[[#This Row],[%SiO2]]<2.43),"T2", IF( AND(VERIF[[#This Row],[%SiO2]]>=2.43,VERIF[[#This Row],[%SiO2]]<=3.24),"T3","T4")) ) -> T1 | L20: Etiquetas de fila | M20: Suma de TONC | N20: Suma de TONC2
A21: 45832 | B21: Malaga | C21: COMPRADA | D21: 138.52 | E21: 0.08 | F21: 53.253333 | G21: =IF(AND(VERIF[[#This Row],[%SiO2]]>=0,VERIF[[#This Row],[%SiO2]]<1.62),"T1", IF( AND(VERIF[[#This Row],[%SiO2]]>=1.62,VERIF[[#This Row],[%SiO2]]<2.43),"T2", IF( AND(VERIF[[#This Row],[%SiO2]]>=2.43,VERIF[[#This Row],[%SiO2]]<=3.24),"T3","T4")) ) -> T1 | L21: T1 | M21: 124146.4 | N21: 0.4795928
A22: 45880 | B22: Carbopar | C22: COMPRADA | D22: 271.04 | E22: 0.08 | F22: 54.192832 | G22: =IF(AND(VERIF[[#This Row],[%SiO2]]>=0,VERIF[[#This Row],[%SiO2]]<1.62),"T1", IF( AND(VERIF[[#This Row],[%SiO2]]>=1.62,VERIF[[#This Row],[%SiO2]]<2.43),"T2", IF( AND(VERIF[[#This Row],[%SiO2]]>=2.43,VERIF[[#This Row],[%SiO2]]<=3.24),"T3","T4")) ) -> T1 | L22: T2 | M22: 59396.086 | N22: 0.22945438
A23: 45973 | B23: Malaga | C23: COMPRADA | D23: 140.3 | E23: 0.085 | F23: 54.6 | G23: =IF(AND(VERIF[[#This Row],[%SiO2]]>=0,VERIF[[#This Row],[%SiO2]]<1.62),"T1", IF( AND(VERIF[[#This Row],[%SiO2]]>=1.62,VERIF[[#This Row],[%SiO2]]<2.43),"T2", IF( AND(VERIF[[#This Row],[%SiO2]]>=2.43,VERIF[[#This Row],[%SiO2]]<=3.24),"T3","T4")) ) -> T1 | L23: T3 | M23: 33050.251 | N23: 0.12767718
A24: 45824 | B24: Carbopar | C24: COMPRADA | D24: 166.62 | E24: 0.09 | F24: 54.637475 | G24: =IF(AND(VERIF[[#This Row],[%SiO2]]>=0,VERIF[[#This Row],[%SiO2]]<1.62),"T1", IF( AND(VERIF[[#This Row],[%SiO2]]>=1.62,VERIF[[#This Row],[%SiO2]]<2.43),"T2", IF( AND(VERIF[[#This Row],[%SiO2]]>=2.43,VERIF[[#This Row],[%SiO2]]<=3.24),"T3","T4")) ) -> T1 | L24: T4 | M24: 42265.197 | N24: 0.16327565
A25: 46032 | B25: Carbopar | C25: COMPRADA | D25: 331.22 | E25: 0.09095 | F25: 54.962196 | G25: =IF(AND(VERIF[[#This Row],[%SiO2]]>=0,VERIF[[#This Row],[%SiO2]]<1.62),"T1", IF( AND(VERIF[[#This Row],[%SiO2]]>=1.62,VERIF[[#This Row],[%SiO2]]<2.43),"T2", IF( AND(VERIF[[#This Row],[%SiO2]]>=2.43,VERIF[[#This Row],[%SiO2]]<=3.24),"T3","T4")) ) -> T1 | L25: Total general | M25: 258857.94 | N25: 1
A26: 45808 | B26: Malaga | C26: COMPRADA | D26: 103.22 | E26: 0.1 | F26: 54.896581 | G26: =IF(AND(VERIF[[#This Row],[%SiO2]]>=0,VERIF[[#This Row],[%SiO2]]<1.62),"T1", IF( AND(VERIF[[#This Row],[%SiO2]]>=1.62,VERIF[[#This Row],[%SiO2]]<2.43),"T2", IF( AND(VERIF[[#This Row],[%SiO2]]>=2.43,VERIF[[#This Row],[%SiO2]]<=3.24),"T3","T4")) ) -> T1
A27: 46004 | B27: Gustavo Quesada | C27: COMPRADA | D27: 45.26 | E27: 0.1 | F27: 53.9 | G27: =IF(AND(VERIF[[#This Row],[%SiO2]]>=0,VERIF[[#This Row],[%SiO2]]<1.62),"T1", IF( AND(VERIF[[#This Row],[%SiO2]]>=1.62,VERIF[[#This Row],[%SiO2]]<2.43),"T2", IF( AND(VERIF[[#This Row],[%SiO2]]>=2.43,VERIF[[#This Row],[%SiO2]]<=3.24),"T3","T4")) ) -> T1
A28: 45782 | B28: Carbopar | C28: COMPRADA | D28: 30.66 | E28: 0.107 | F28: 54.535227 | G28: =IF(AND(VERIF[[#This Row],[%SiO2]]>=0,VERIF[[#This Row],[%SiO2]]<1.62),"T1", IF( AND(VERIF[[#This Row],[%SiO2]]>=1.62,VERIF[[#This Row],[%SiO2]]<2.43),"T2", IF( AND(VERIF[[#This Row],[%SiO2]]>=2.43,VERIF[[#This Row],[%SiO2]]<=3.24),"T3","T4")) ) -> T1
A29: 45832 | B29: Carbopar | C29: COMPRADA | D29: 101.89 | E29: 0.11 | F29: 55.175305 | G29: =IF(AND(VERIF[[#This Row],[%SiO2]]>=0,VERIF[[#This Row],[%SiO2]]<1.62),"T1", IF( AND(VERIF[[#This Row],[%SiO2]]>=1.62,VERIF[[#This Row],[%SiO2]]<2.43),"T2", IF( AND(VERIF[[#This Row],[%SiO2]]>=2.43,VERIF[[#This Row],[%SiO2]]<=3.24),"T3","T4")) ) -> T1
A30: 45849 | B30: Carbopar | C30: COMPRADA | D30: 367.16 | E30: 0.11 | F30: 53.351882 | G30: =IF(AND(VERIF[[#This Row],[%SiO2]]>=0,VERIF[[#This Row],[%SiO2]]<1.62),"T1", IF( AND(VERIF[[#This Row],[%SiO2]]>=1.62,VERIF[[#This Row],[%SiO2]]<2.43),"T2", IF( AND(VERIF[[#This Row],[%SiO2]]>=2.43,VERIF[[#This Row],[%SiO2]]<=3.24),"T3","T4")) ) -> T1
A31: 45952 | B31: Malaga | C31: COMPRADA | D31: 95.35 | E31: 0.11 | F31: 55.1 | G31: =IF(AND(VERIF[[#This Row],[%SiO2]]>=0,VERIF[[#This Row],[%SiO2]]<1.62),"T1", IF( AND(VERIF[[#This Row],[%SiO2]]>=1.62,VERIF[[#This Row],[%SiO2]]<2.43),"T2", IF( AND(VERIF[[#This Row],[%SiO2]]>=2.43,VERIF[[#This Row],[%SiO2]]<=3.24),"T3","T4")) ) -> T1
A32: 45954 | B32: Afloramiento 1 | C32: PROPIA | D32: 44.78 | E32: 0.11 | F32: 54.8 | G32: =IF(AND(VERIF[[#This Row],[%SiO2]]>=0,VERIF[[#This Row],[%SiO2]]<1.62),"T1", IF( AND(VERIF[[#This Row],[%SiO2]]>=1.62,VERIF[[#This Row],[%SiO2]]<2.43),"T2", IF( AND(VERIF[[#This Row],[%SiO2]]>=2.43,VERIF[[#This Row],[%SiO2]]<=3.24),"T3","T4")) ) -> T1
A33: 46000 | B33: Carbopar | C33: COMPRADA | D33: 344.33 | E33: 0.11 | F33: 54.9 | G33: =IF(AND(VERIF[[#This Row],[%SiO2]]>=0,VERIF[[#This Row],[%SiO2]]<1.62),"T1", IF( AND(VERIF[[#This Row],[%SiO2]]>=1.62,VERIF[[#This Row],[%SiO2]]<2.43),"T2", IF( AND(VERIF[[#This Row],[%SiO2]]>=2.43,VERIF[[#This Row],[%SiO2]]<=3.24),"T3","T4")) ) -> T1
A34: 45829 | B34: Carbopar | C34: COMPRADA | D34: 488.99 | E34: 0.12 | F34: 53.822969 | G34: =IF(AND(VERIF[[#This Row],[%SiO2]]>=0,VERIF[[#This Row],[%SiO2]]<1.62),"T1", IF( AND(VERIF[[#This Row],[%SiO2]]>=1.62,VERIF[[#This Row],[%SiO2]]<2.43),"T2", IF( AND(VERIF[[#This Row],[%SiO2]]>=2.43,VERIF[[#This Row],[%SiO2]]<=3.24),"T3","T4")) ) -> T1
A35: 45912 | B35: Malaga | C35: COMPRADA | D35: 99.32 | E35: 0.12 | F35: 54.565056 | G35: =IF(AND(VERIF[[#This Row],[%SiO2]]>=0,VERIF[[#This Row],[%SiO2]]<1.62),"T1", IF( AND(VERIF[[#This Row],[%SiO2]]>=1.62,VERIF[[#This Row],[%SiO2]]<2.43),"T2", IF( AND(VERIF[[#This Row],[%SiO2]]>=2.43,VERIF[[#This Row],[%SiO2]]<=3.24),"T3","T4")) ) -> T1
A36: 45708 | B36: Carbopar | C36: COMPRADA | D36: 522.36 | E36: 0.136425 | F36: 53.979748 | G36: =IF(AND(VERIF[[#This Row],[%SiO2]]>=0,VERIF[[#This Row],[%SiO2]]<1.62),"T1", IF( AND(VERIF[[#This Row],[%SiO2]]>=1.62,VERIF[[#This Row],[%SiO2]]<2.43),"T2", IF( AND(VERIF[[#This Row],[%SiO2]]>=2.43,VERIF[[#This Row],[%SiO2]]<=3.24),"T3","T4")) ) -> T1
A37: 45997 | B37: Carbopar | C37: COMPRADA | D37: 36.68 | E37: 0.14 | F37: 53.4 | G37: =IF(AND(VERIF[[#This Row],[%SiO2]]>=0,VERIF[[#This Row],[%SiO2]]<1.62),"T1", IF( AND(VERIF[[#This Row],[%SiO2]]>=1.62,VERIF[[#This Row],[%SiO2]]<2.43),"T2", IF( AND(VERIF[[#This Row],[%SiO2]]>=2.43,VERIF[[#This Row],[%SiO2]]<=3.24),"T3","T4")) ) -> T1
... A714: 45986 | B714: Afloramiento 1 Sur | C714: PROPIA | D714: 293.32 | E714: 2.2 | F714: 52.5 | G714: =IF(AND(VERIF[[#This Row],[%SiO2]]>=0,VERIF[[#This Row],[%SiO2]]<1.62),"T1", IF( AND(VERIF[[#This Row],[%SiO2]]>=1.62,VERIF[[#This Row],[%SiO2]]<2.43),"T2", IF( AND(VERIF[[#This Row],[%SiO2]]>=2.43,VERIF[[#This Row],[%SiO2]]<=3.24),"T3","T4")) ) -> T2
A715: 45989 | C715: NA | D715: 193.2 | E715: 2.2 | F715: 52.1 | G715: =IF(AND(VERIF[[#This Row],[%SiO2]]>=0,VERIF[[#This Row],[%SiO2]]<1.62),"T1", IF( AND(VERIF[[#This Row],[%SiO2]]>=1.62,VERIF[[#This Row],[%SiO2]]<2.43),"T2", IF( AND(VERIF[[#This Row],[%SiO2]]>=2.43,VERIF[[#This Row],[%SiO2]]<=3.24),"T3","T4")) ) -> T2
A716: 45988 | B716: Afloramiento 1 Sur | C716: PROPIA | D716: 193.02 | E716: 2.2 | F716: 52.1 | G716: =IF(AND(VERIF[[#This Row],[%SiO2]]>=0,VERIF[[#This Row],[%SiO2]]<1.62),"T1", IF( AND(VERIF[[#This Row],[%SiO2]]>=1.62,VERIF[[#This Row],[%SiO2]]<2.43),"T2", IF( AND(VERIF[[#This Row],[%SiO2]]>=2.43,VERIF[[#This Row],[%SiO2]]<=3.24),"T3","T4")) ) -> T2
...

Sheet PARAMETROS
A1: COMPRADA | B1: PROPIA
A2: Malaga | B2: Caliza Propia
A3: Gustavo Quesada | B3: Afloramiento 1
A4: Caribbean | B4: Malsitio
A5: Carbopar | B5: Afloramiento 1 Sur
A6: Leonidas Rodriguez
A7: Calizas & Granitos
A8: Lisandro Rojas
